Workbook

Sheet Admin_Inputs
A2: Drivers de l'Opération | E2: Drivers d'Exploitation | I2: Drivers de Financement
A3: Driver | B3: Valeur | E3: Driver | F3: Valeur | I3: Driver | J3: Valeur
A4: Multiple d'Entrée (EV/EBITDA) | B4: =_xlfn.XLOOKUP(Setup!E4, SectBenchTable[sector], SectBenchTable[target_ebitda_mult]) -> 9.5 | E4: Croissance Annuelle du Revenu | F4: =_xlfn.XLOOKUP(Setup!B2, Table_Data[symbol], Table_Data[avg_revenue_growth]) -> 0.1418 | I4: Taux d'Intérêt (%) | J4: 0.08
A5: Frais de Transaction (%) | B5: 0.03 | E5: Marge d'EBITDA Cible | F5: =_xlfn.XLOOKUP(Setup!E4, SectBenchTable[sector], SectBenchTable[ebitda_margin_target]) -> 0.18 | I5: Taux d'Impôt (IS) | J5: =_xlfn.XLOOKUP(Setup!E5,TaxTable[country_name],TaxTable[tax_rate] ) -> 0.25
A6: Levier Senior (x EBITDA) | B6: 5x | E6: Intensité du Capex (%) | F6: =Setup!E9 -> 0.0159 | I6: Horizon de Détention | J6: 5
A7: Management Roll-over (%) | B7: 0.15 | E7: Variation du BFR (% CA) | F7: =_xlfn.XLOOKUP(Setup!E4, SectBenchTable[sector], SectBenchTable[nwc_variation_revenue]) -> 0.08 | I7: Multiple de Sortie | J7: =B4 -> 9.5

Sheet Setup
B2: ACS.MC | D2: Métrique | E2: Valeur
B3: SELECTION | D3: Nom de l'entreprise | E3: =_xlfn.XLOOKUP($B$2, Table_Data[symbol], Table_Data[name]) -> ACS, Actividades de Construcción y Servicios, S.A.
D4: Secteur | E4: =_xlfn.XLOOKUP(B2,Table_Data[symbol], Table_Data[sector]) -> Industrials
D5: Country | E5: =_xlfn.XLOOKUP(B2,Table_Data[symbol], Table_Data[country]) -> Spain
D6: EBITDA (T0) | E6: =_xlfn.XLOOKUP($B$2, Table_Data[symbol], Table_Data[EBITDA]) -> 2702859000
D7: Dette Nette (T0) | E7: =_xlfn.XLOOKUP($B$2, Table_Data[symbol], Table_Data[Net_Debt]) -> 2791044000
D8: SAI Score | E8: =_xlfn.XLOOKUP($B$2, Table_Data[symbol], Table_Data[SAI_Score]) -> 11.443139
D9: Capex Intensity | E9: =_xlfn.XLOOKUP($B$2, Table_Data[symbol], Table_Data[capex_intensity]) -> 0.0159
D10: Cap | E10: =_xlfn.XLOOKUP(Setup!B2, Table_Data[symbol], Table_Data[market_cap]) -> 27067064320

Sheet LBO_Temp
B2: LBO | C2: =Setup!E3 -> ACS, Actividades de Construcción y Servicios, S.A.
B4: Hypothèses
B6: Entry | G6: Financials | L6: Capital Structure | N6: Montant | O6: Coût
B7: LTM EBITDA | E7: =J9 -> 2702859000 | G7: LTM Financials | L7: Dette Bancaire | N7: 4 | O7: 0.06
B8: EBITDA Multiple | E8: =AVERAGE(Admin_Inputs!B4, _xlfn.XLOOKUP(Setup!B2, Table_Data[symbol], Table_Data[RealMultiple])) -> 9.7571173 | G8: Chiffre d'Affaires | J8: =_xlfn.XLOOKUP(Setup!B2, Table_Data[symbol], Table_Data[Revenue]) -> 41633120000 | L8: Obligations Senior | N8: 2 | O8: 0.12
B9: Valeur d'Entreprise | E9: =E7*E8 -> 26372112410 | G9: EBITDA | J9: =Setup!E6 -> 2702859000
B10: Dette Nette Existante | E10: =Setup!E7 -> 2791044000 | G10: D&A | J10: =_xlfn.XLOOKUP(Setup!B2, Table_Data[symbol], Table_Data[depreciation_amortization]) -> 969658000 | L10: For Reference
B11: Valeur des Fonds Propres | E11: =E9-E10 -> 23581068410 | G11: Capex | J11: =_xlfn.XLOOKUP(Setup!B2, Table_Data[symbol], Table_Data[Capex]) -> 612491000 | L11: TRI | O11: =O106 -> 0.29725109
G12: BFR | J12: =Setup!E6 -LBO_Temp!J11-(_xlfn.XLOOKUP(Setup!B2, Table_Data[symbol], Table_Data[fcf_yield]))*Setup!E10 -> -2.2657271e+08
B13: Frais et commissions | E13: =J8*Admin_Inputs!B5 -> 1248993600
G14: Operating Assumptions
B15: Sortie | G15: Revenue Growth | J15: =(Admin_Inputs!F4+ (_xlfn.XLOOKUP(Setup!E4, SectBenchTable[sector], SectBenchTable[annual_growth])))/2 -> 0.0884
B16: EBITDA Multiple | E16: =E8 -> 9.7571173 | G16: YoY margin expansion | J16: 0.003
G17: Tax Rate | J17: =Admin_Inputs!J5 -> 0.25
B19: Ressources et Emplois
B21: Ressources | J21: Emplois
E22: Monant | F22: xEBITDA | G22: % Capital | M22: Monant | N22: xEBITDA | O22: % Capital
B23: =L7 -> Dette Bancaire | E23: =F23*$J$9 -> 10811436000 | F23: =N7 -> 4 | G23: =E23/$E$29 -> 0.39141937 | J23: Remboursement de la dette | M23: =E10 -> 2791044000 | N23: =M23/$J$9 -> 1.0326266 | O23: =M23/$M$29 -> 0.10104751
B24: =L8 -> Obligations Senior | E24: =F24*$J$9 -> 5405718000 | F24: =N8 -> 2 | G24: =E24/$E$29 -> 0.19570969 | J24: Paiement des titres | M24: =E11 -> 23581068410 | N24: =M24/$J$9 -> 8.7244908 | O24: =M24/$M$29 -> 0.85373368
B25: Total Debt | E25: =E23+E24 -> 16217154000 | F25: =E25/J9 -> 6 | G25: =E25/$E$29 -> 0.58712906
J26: Frais et commissions | M26: =E13 -> 1248993600 | N26: =M26/$J$9 -> 0.46210091 | O26: =M26/$M$29 -> 0.045218812
B27: Apport en fonds propres | E27: =E29-E25 -> 11403952010 | F27: =E27/J9 -> 4.2192182 | G27: =E27/$E$29 -> 0.41287094
B29: Total Sources | E29: =M29 -> 27621106010 | F29: =E29/J9 -> 10.219218 | G29: =E29/$E$29 -> 1 | J29: Total Uses | M29: =M23+M24+M26 -> 27621106010 | N29: =N23+N24+N26 -> 10.219218 | O29: =M29/$M$29 -> 1
B32: Financials
B34: Operating Model | J34: Year 0 | K34: Year 1 | L34: Year 2 | M34: Year 3 | N34: Year 4 | O34: Year 5
B35: Revenue | J35: =J8 -> 41633120000 | K35: =J35*(1+K36) -> 45313487808 | L35: =K35*(1+L36) -> 4.93192e+10 | M35: =L35*(1+M36) -> 5.3679017e+10 | N35: =M35*(1+N36) -> 5.8424243e+10 | O35: =N35*(1+O36) -> 6.3588946e+10
B36: % growth | K36: =$J$15 -> 0.0884 | L36: =K36 -> 0.0884 | M36: =L36 -> 0.0884 | N36: =M36 -> 0.0884 | O36: =N36 -> 0.0884
B38: EBITDA | J38: =J9 -> 2702859000 | K38: =K39*K35 -> 3.0777322e+09 | L38: =L39*L35 -> 3.4977613e+09 | M38: =M39*M35 -> 3.9680005e+09 | N38: =N39*N35 -> 4.4940444e+09 | O38: =O39*O35 -> 5.0820848e+09
B39: % sales | J39: =J38/J35 -> 0.064920885 | K39: =J39+$J$16 -> 0.067920885 | L39: =K39+$J$16 -> 0.070920885 | M39: =L39+$J$16 -> 0.073920885 | N39: =M39+$J$16 -> 0.076920885 | O39: =N39+$J$16 -> 0.079920885
B41: EBIT | J41: =J38-J56 -> 1733201000 | K41: =K38-K56 -> 2.0223564e+09 | L41: =L38-L56 -> 2.3490903e+09 | M41: =M38-M56 -> 2.717787e+09 | N41: =N38-N56 -> 3.1333121e+09 | O41: =O38-O56 -> 3.6010637e+09
B42: % sales | J42: =J41/J35 -> 0.041630341 | K42: =K41/K35 -> 0.044630341 | L42: =L41/L35 -> 0.047630341 | M42: =M41/M35 -> 0.050630341 | N42: =N41/N35 -> 0.053630341 | O42: =O41/O35 -> 0.056630341
B44: Interest | K44: =K91 -> 1297372320 | L44: =L91 -> 1.2402219e+09 | M44: =M91 -> 1.1636285e+09 | N44: =N91 -> 1.0646373e+09 | O44: =O91 -> 9.3992448e+08
B46: EBT | K46: =K41-K44 -> 7.2498411e+08 | L46: =L41-L44 -> 1.1088685e+09 | M46: =M41-M44 -> 1.5541585e+09 | N46: =N41-N44 -> 2.0686748e+09 | O46: =O41-O44 -> 2.6611392e+09
B47: % sales | K47: =K46/K35 -> 0.015999301 | L47: =L46/L35 -> 0.022483505 | M47: =M46/M35 -> 0.028952812 | N47: =N46/N35 -> 0.035407815 | O47: =O46/O35 -> 0.041849085
B49: Taxes | K49: =K46*K50 -> 1.8124603e+08 | L49: =L46*L50 -> 2.7721712e+08 | M49: =M46*M50 -> 3.8853962e+08 | N49: =N46*N50 -> 5.171687e+08 | O49: =O46*O50 -> 6.652848e+08
B50: % tax rate | K50: =J17 -> 0.25 | L50: =K50 -> 0.25 | M50: =L50 -> 0.25 | N50: =M50 -> 0.25 | O50: =N50 -> 0.25
B52: Net Income | K52: =K46-K49 -> 5.4373808e+08 | L52: =L46-L49 -> 8.3165136e+08 | M52: =M46-M49 -> 1.1656189e+09 | N52: =N46-N49 -> 1.5515061e+09 | O52: =O46-O49 -> 1.9958544e+09
B53: % sales | K53: =K52/K35 -> 0.011999475 | L53: =L52/L35 -> 0.016862629 | M53: =M52/M35 -> 0.021714609 | N53: =N52/N35 -> 0.026555861 | O53: =O52/O35 -> 0.031386814
B55: Cash flow Items | J55: Year 0 | K55: Year 1 | L55: Year 2 | M55: Year 3 | N55: Year 4 | O55: Year 5
B56: D&A | J56: =J10 -> 969658000 | K56: =K57*K35 -> 1.0553758e+09 | L56: =L57*L35 -> 1.148671e+09 | M56: =M57*M35 -> 1.2502135e+09 | N56: =N57*N35 -> 1.3607324e+09 | O56: =O57*O35 -> 1.4810211e+09
...

Sheet dim_company
A1: Company_ID | B1: symbol | C1: name | D1: sector | E1: country | F1: market_cap | G1: ebitda_margin | H1: fcf_yield | I1: net_debt_ebitda | J1: capex_intensity | K1: dscr | L1: avg_revenue_growth | M1: volatility | N1: depreciation_amortization | O1: ev_ebitda | P1: Fiscal_Year | Q1: Revenue | R1: EBITDA | S1: EBIT | T1: Net_Income | U1: Total_Assets | V1: Total_Debt | W1: Cash | X1: Net_Debt | Y1: Capex | Z1: Date | AA1: Share_Price | AB1: Shares_Outstanding | AC1: LBO_Score | AD1: Op_Efficiency_Score | AE1: Deep_Value_Score | AF1: Bankruptcy_Risk_AltmanZ | AG1: Score_Serviceability | AH1: Score_Optimization | AI1: Score_Collateral | AJ1: SAI_Score | AK1: RealMultiple
A2: 1 | B2: JUN3.DE | C2: Jungheinrich Aktiengesellschaft | D2: Industrials | E2: Germany | F2: 3119160064 | G2: 0.1685 | H2: 0.1409 | I2: 0.19 | J2: 0.0257 | K2: 24.45 | L2: 0.0867 | N2: 467553000 | O2: 15.49 | P2: 2024 | Q2: 5391884000 | R2: 908550000 | S2: 440997000 | T2: 288993000 | U2: 7128360000 | V2: 696129000 | W2: 524856000 | X2: 171273000 | Y2: 138426000 | Z2: 46083 | AA2: 31.2 | AB2: 48000000 | AC2: 18.6098 | AD2: 6.4763 | AE2: 16.7046 | AF2: 0.2855 | AG2: 18.609843 | AH2: 6.4763356 | AI2: 16.704625 | AJ2: 14.398226 | AK2: 3.4331188
A3: 52 | B3: AALB.AS | C3: Aalberts N.V. | D3: Industrials | E3: Netherlands | F3: 3595531264 | G3: 0.1623 | H3: 0.0472 | I3: 1.17 | J3: 0.0835 | K3: 16.49 | L3: -0.014 | N3: 225800000 | O3: 9.16 | P3: 2024 | Q3: 3148600000 | R3: 511100000 | S3: 292600000 | T3: 179100000 | U3: 4230000000 | V3: 686600000 | W3: 89800000 | X3: 596800000 | Y3: 262900000 | Z3: 46083 | AA3: 34.68 | AB3: 108035683 | AC3: 14.0664 | AD3: 6.2748 | AE3: 10.2703 | AF3: -0.4412 | AG3: 14.0664 | AH3: 6.2748324 | AI3: 10.270256 | AJ3: 10.590087 | AK3: 7.034888
A4: 2 | B4: VIS.MC | C4: Viscofan, S.A. | D4: Consumer Cyclical | E4: Spain | F4: 2669550080 | G4: 0.2497 | H4: 0.0602 | I4: 0.52 | J4: 0.0623 | K4: 28.99 | L4: 0.0142 | N4: 85196000 | O4: 10.11 | P4: 2024 | Q4: 1203994000 | R4: 300602000 | S4: 216808000 | T4: 157019000 | U4: 1402848000 | V4: 212951000 | W4: 55143000 | X4: 157808000 | Y4: 75027000 | Z4: 46083 | AA4: 58 | AB4: 45746258 | AC4: 14.6968 | AD4: 9.1154 | AE4: 13.6114 | AF4: 0.0719 | AG4: 14.69676 | AH4: 9.1153768 | AI4: 13.611411 | AJ4: 12.696741 | AK4: 8.8806797
A5: 4 | B5: UBI.PA | C5: Ubisoft Entertainment SA | D5: Communication Services | E5: France | F5: 541744832 | G5: 0.3529 | H5: 0.2342 | I5: 1.75 | J5: 0.0221 | K5: 6.31 | L5: -0.0176 | N5: 710700000 | O5: -11.95 | P5: 2024 | Q5: 2300900000 | R5: 1105500000 | S5: 329400000 | T5: 157800000 | U5: 5121600000 | V5: 2509400000 | W5: 1205200000 | X5: 1304200000 | Y5: 116200000 | Z5: 46083 | AA5: 4.125 | AB5: 134728884 | AC5: 23.1339 | AD5: 12.4694 | AE5: 8.6224 | AF5: -0.2986 | AG5: 23.133891 | AH5: 12.469429 | AI5: 8.6223892 | AJ5: 15.581102 | AK5: 0.49004508
A6: 3 | B6: GRG.L | C6: Greggs plc | D6: Consumer Cyclical | E6: United Kingdom | F6: 1671173760 | G6: 0.1776 | H6: 0.0419 | I6: 0.81 | J6: 0.1196 | K6: 25.74 | L6: 0.1799 | N6: 140000000 | O6: 7.4 | P6: 2024 | Q6: 2014400000 | R6: 357800000 | S6: 217800000 | T6: 153400000 | U6: 1319700000 | V6: 415100000 | W6: 125300000 | X6: 289800000 | Y6: 240900000 | Z6: 46083 | AA6: 1559 | AB6: 101838742 | AC6: 13.8094 | AD6: 6.7721 | AE6: 11.8243 | AF6: -0.2142 | AG6: 13.809407 | AH6: 6.7720902 | AI6: 11.824255 | AJ6: 11.102666 | AK6: 4.6706925
A7: 136 | B7: ACKB.BR | C7: Ackermans & Van Haaren NV | D7: Industrials | E7: Belgium | F7: 8962184192 | G7: 0.2065 | H7: 0.1227 | I7: 5.34 | J7: 0.0513 | L7: 0.1101 | N7: 536485000 | O7: 8.3 | P7: 2024 | Q7: 6043334000 | R7: 1248085000 | S7: 807748000 | T7: 459871000 | U7: 20291367000 | V7: 9953790000 | W7: 3292681000 | X7: 6661109000 | Y7: 310160000 | Z7: 46085 | AA7: 274.4 | AB7: 32728537 | AC7: 17.7273 | AD7: 7.7114 | AE7: 5.1313 | AF7: -2.7844 | AG7: 17.727339 | AH7: 7.7113549 | AI7: 5.1313148 | AJ7: 10.943736 | AK7: 7.1807483
A8: 5 | B8: DEQ.DE | C8: Deutsche EuroShop AG | D8: Real Estate | E8: Germany | F8: 1440449152 | G8: 0.7343 | H8: 0.1114 | I8: 8.01 | J8: 0.0001 | K8: 4.06 | L8: 0.0941 | N8: 140000 | O8: 15.22 | P8: 2024 | Q8: 271403000 | R8: 199291000 | S8: 199151000 | T8: 123514000 | U8: 4364405000 | V8: 1809108000 | W8: 212438000 | X8: 1596670000 | Y8: 15000 | Z8: 46083 | AA8: 20.55 | AB8: 75023389 | AC8: 17.1794 | AD8: 24.8651 | AE8: 4.3388 | AF8: -3.7689 | AG8: 17.17941 | AH8: 24.865123 | AI8: 4.338843 | AJ8: 15.632954 | AK8: 7.2278686
A9: 92 | B9: ACS.MC | C9: ACS, Actividades de Construcción y Servicios, S.A. | D9: Industrials | E9: Spain | F9: 27067064320 | G9: 0.0706 | H9: 0.0856 | I9: 0.52 | J9: 0.0159 | L9: 0.1418 | N9: 969658000 | O9: 14.14 | P9: 2024 | Q9: 41633120000 | R9: 2702859000 | S9: 1836656000 | T9: 827580000 | U9: 42025282000 | V9: 14204703000 | W9: 11413659000 | X9: 2791044000 | Y9: 612491000 | Z9: 46085 | AA9: 103.7 | AB9: 260510722 | AC9: 15.9284 | AD9: 3.2945 | AE9: 13.6114 | AF9: -0.1074 | AG9: 15.928387 | AH9: 3.2945359 | AI9: 13.611411 | AJ9: 11.443139 | AK9: 10.014235
A10: 6 | B10: AMP.MI | C10: Amplifon S.p.A. | D10: Healthcare | E10: Italy | F10: 2711829248 | G10: 0.2313 | H10: 0.1124 | I10: 2.57 | J10: 0.0608 | K10: 9.65 | L10: 0.0734 | N10: 302718000 | O10: 13.38 | P10: 2024 | Q10: 2409241000 | R10: 557254000 | S10: 254536000 | T10: 145374000 | U10: 3992762000 | V10: 1721518000 | W10: 288834000 | X10: 1432684000 | Y10: 146421000 | Z10: 46083 | AA10: 12.845 | AB10: 219937482 | AC10: 17.2279 | AD10: 8.5174 | AE10: 7.2063 | AF10: -1.1071 | AG10: 17.2279 | AH10: 8.5173675 | AI10: 7.2062708 | AJ10: 11.608251 | AK10: 4.866415
A11: 11 | B11: DIA.MI | C11: DiaSorin S.p.A. | D11: Healthcare | E11: Italy | F11: 3673987072 | G11: 0.3366 | H11: 0.0651 | I11: 1.68 | J11: 0.101 | K11: 14.48 | L11: -0.0081 | N11: 129041000 | O11: 11.34 | P11: 2024 | Q11: 1185427000 | R11: 399044000 | S11: 270003000 | T11: 188105000 | U11: 3304920000 | V11: 1014189000 | W11: 344270000 | X11: 669919000 | Y11: 119716000 | Z11: 46083 | AA11: 70.44 | AB11: 52679895 | AC11: 14.9344 | AD11: 11.9397 | AE11: 8.7834 | AF11: -0.5129 | AG11: 14.934358 | AH11: 11.939671 | AI11: 8.783423 | AJ11: 12.190671 | AK11: 9.2069723
A12: 7 | B12: IRE.MI | C12: Iren SpA | D12: Utilities | E12: Italy | F12: 3382187520 | G12: 0.2076 | H12: 0.0748 | I12: 0.23 | J12: 0.1396 | K12: 8.57 | L12: 0.1133 | N12: 655475000 | O12: 6.62 | P12: 2024 | Q12: 5949243000 | R12: 1234819000 | S12: 579344000 | T12: 268471000 | U12: 12211318000 | V12: 614151000 | W12: 326568000 | X12: 287583000 | Y12: 830217000 | Z12: 46083 | AA12: 2.81 | AB12: 1283075732 | AC12: 15.4047 | AD12: 7.7471 | AE12: 16.2413 | AF12: 0.2158 | AG12: 15.404703 | AH12: 7.7471054 | AI12: 16.241291 | AJ12: 13.3584 | AK12: 2.7390148
A13: 35 | B13: ADV.DE | C13: Adtran Networks SE | D13: Technology | E13: Germany | F13: 1166020736 | G13: 0.0957 | H13: 0.0005 | I13: 1.77 | J13: 0.1427 | K13: 8.21 | L13: -0.0813 | N13: 83698000 | O13: 142.25 | P13: 2024 | Q13: 438085000 | R13: 41926000 | S13: -41772000 | T13: -62701000 | U13: 670003000 | V13: 97220000 | W13: 23049000 | X13: 74171000 | Y13: 62495000 | Z13: 46083 | AA13: 22.3 | AB13: 52054500 | AC13: 11.802 | AD13: 4.1103 | AE13: 8.5779 | AF13: -0.9465 | AG13: 11.801952 | AH13: 4.1102986 | AI13: 8.5778744 | AJ13: 8.5272326 | AK13: 27.8114
A14: 8 | B14: JUVE.MI | C14: Juventus Football Club S.p.A. | D14: Communication Services | E14: Italy | F14: 855298880 | G14: -0.0498 | H14: -0.24 | I14: -12.41 | J14: 0.405 | K14: -0.81 | L14: -0.0514 | N14: 152391000 | O14: 18.76 | P14: 2024 | Q14: 393112000 | R14: -19570000 | S14: -171961000 | T14: -199229000 | U14: 678980000 | V14: 279263000 | W14: 36424000 | X14: 242839000 | Y14: 159206000 | Z14: 46083 | AA14: 2.292 | AB14: 379121815 | AC14: 1 | AD14: 1 | AE14: 1 | AF14: 7.0502 | AG14: 1 | AH14: 1 | AI14: 1 | AJ14: 1 | AK14: -43.704593
A15: 9 | B15: BME.L | C15: B&M European Value Retail S.A. | D15: Consumer Defensive | E15: Luxembourg | F15: 1865753088 | G15: 0.1515 | H15: 0.2905 | I15: 2.78 | J15: 0.0239 | K15: 6.03 | L15: 0.0609 | N15: 273000000 | O15: 7.15 | P15: 2024 | Q15: 5484000000 | R15: 872000000 | S15: 614000000 | T15: 367000000 | U15: 3625000000 | V15: 2267000000 | W15: 182000000 | X15: 2085000000 | Y15: 126000000 | Z15: 46083 | AA15: 189.04 | AB15: 1005038256 | AC15: 25 | AD15: 5.9238 | AE15: 6.9424 | AF15: -1.0795 | AG15: 25 | AH15: 5.9238269 | AI15: 6.9424276 | AJ15: 13.859876 | AK15: 2.1396251
A16: 99 | B16: AENA.MC | C16: Aena S.M.E., S.A. | D16: Industrials | E16: Spain | F16: 37874999296 | G16: 0.6208 | H16: 0.0456 | I16: 0.81 | J16: 0.1423 | L16: 0.1453 | N16: 796897000 | O16: 11.8 | P16: 2024 | Q16: 5763531000 | R16: 3649239000 | S16: 2801428000 | T16: 1934224000 | U16: 16975364000 | V16: 7011662000 | W16: 1821283000 | X16: 5190379000 | Y16: 825184000 | Z16: 46085 | AA16: 25.26 | AB16: 1500000000 | AC16: 13.9888 | AD16: 21.1763 | AE16: 11.8243 | AF16: 0.3228 | AG16: 13.988817 | AH16: 21.176315 | AI16: 11.824255 | AJ16: 15.495698 | AK16: 10.378876
A17: 10 | B17: ASHM.L | C17: Ashmore Group Plc | D17: Financial Services | E17: United Kingdom | F17: 1453789312 | G17: 0.7756 | H17: 0.0333 | I17: -3.07 | J17: 0.0014 | K17: 373.33 | L17: -0.1661 | N17: 3100000 | O17: 22.86 | P17: 2024 | Q17: 189000000 | R17: 131500000 | S17: 128400000 | T17: 93700000 | U17: 979700000 | V17: 6400000 | W17: 511800000 | X17: -505400000 | Y17: 800000 | Z17: 46083 | AA17: 231.4 | AB17: 650149952 | AC17: 13.3924 | AD17: 25 | AE17: 1 | AF17: 2.8193 | AG17: 13.392399 | AH17: 25 | AI17: 1 | AJ17: 13.15696 | AK17: 11.055432
A18: 32 | B18: TEP.PA | C18: Teleperformance SE | D18: Industrials | E18: France | F18: 3191384576 | G18: 0.1856 | H18: 0.4995 | I18: 2.02 | J18: 0.0213 | K18: 7.34 | L18: 0.0828 | N18: 739000000 | O18: 4.44 | P18: 2024 | Q18: 10280000000 | R18: 1908000000 | S18: 1129000000 | T18: 523000000 | U18: 12074000000 | V18: 4907000000 | W18: 1058000000 | X18: 3849000000 | Y18: 219000000 | Z18: 46083 | AA18: 49.6 | AB18: 58130862 | AC18: 25 | AD18: 7.0321 | AE18: 8.0712 | AF18: -0.29 | AG18: 25 | AH18: 7.0320943 | AI18: 8.0711872 | AJ18: 14.530984 | AK18: 1.6726334
A19: 43 | B19: AFX.DE | C19: Carl Zeiss Meditec AG | D19: Healthcare | E19: Germany | F19: 2232169984 | G19: 0.1557 | H19: 0.0597 | I19: 0.3 | J19: 0.0344 | K19: 13.03 | L19: 0.055 | N19: 126378000 | O19: 10.42 | P19: 2024 | Q19: 2066127000 | R19: 403061000 | S19: 270290000 | T19: 178726000 | U19: 3393200000 | V19: 151347000 | W19: 20285000 | X19: 131062000 | Y19: 152204000 | Z19: 46083 | AA19: 26.58 | AB19: 87536079 | AC19: 14.6725 | AD19: 6.0603 | AE19: 15.4991 | AF19: 0.0904 | AG19: 14.672516 | AH19: 6.0603291 | AI19: 15.499065 | AJ19: 12.336825 | AK19: 5.5380451
A20: 12 | B20: GNS.L | C20: Genus plc | D20: Healthcare | E20: United Kingdom | F20: 1823043072 | G20: 0.1393 | H20: 0.0267 | I20: 2.33 | J20: 0.0276 | K20: 4.57 | L20: 0.046 | N20: 44700000 | O20: 21.52 | P20: 2024 | Q20: 668800000 | R20: 73700000 | S20: 26800000 | T20: 7900000 | U20: 987800000 | V20: 291200000 | W20: 42500000 | X20: 248700000 | Y20: 24700000 | Z20: 46083 | AA20: 2870 | AB20: 66413228 | AC20: 13.0724 | AD20: 5.5273 | AE20: 7.5486 | AF20: -1.1935 | AG20: 13.07237 | AH20: 5.5273207 | AI20: 7.5485539 | AJ20: 9.1517105 | AK20: 24.735998
A21: 31 | B21: IMCD.AS | C21: IMCD N.V. | D21: Basic Materials | E21: Netherlands | F21: 4417032704 | G21: 0.1127 | H21: 0.0684 | I21: 2.72 | J21: 0.0056 | K21: 8.12 | L21: 0.0135 | N21: 142918000 | O21: 11.2 | P21: 2024 | Q21: 4727602000 | R21: 606812000 | S21: 452528000 | T21: 278243000 | U21: 4878261000 | V21: 1695652000 | W21: 522780000 | X21: 1172872000 | Y21: 26452000 | Z21: 46083 | AA21: 79.22 | AB21: 59032832 | AC21: 15.0944 | AD21: 4.6628 | AE21: 7.0148 | AF21: -1.401 | AG21: 15.094372 | AH21: 4.6628072 | AI21: 7.0147717 | AJ21: 9.5410226 | AK21: 7.2790794
A22: 13 | B22: COFB.BR | C22: Cofinimmo SA | D22: Real Estate | E22: Belgium | F22: 3206888960 | G22: 0.7352 | H22: 0.0869 | I22: 10.02 | J22: 0.0012 | K22: 6.81 | L22: -0.0136 | N22: 1856000 | O22: 23.43 | Z22: 46083 | AA22: 91.45 | AB22: 38086569 | AC22: 15.9914 | AD22: 24.8944 | AE22: 3.9956 | AF22: -5.0081 | AG22: 15.991423 | AH22: 24.894373 | AI22: 3.9956201 | AJ22: 15.063567
A23: 14 | B23: VOS.DE | C23: Vossloh AG | D23: Industrials | E23: Germany | F23: 1497346304 | G23: 0.1361 | H23: 0.0539 | I23: 0.96 | J23: 0.046 | K23: 8.76 | L23: 0.0888 | N23: 55200000 | O23: 12.97 | P23: 2024 | Q23: 1209600000 | R23: 164600000 | S23: 109400000 | T23: 69200000 | U23: 1490800000 | V23: 253500000 | W23: 94700000 | X23: 158800000 | Y23: 55700000 | Z23: 46083 | AA23: 80.2 | AB23: 19320597 | AC23: 14.3913 | AD23: 5.4233 | AE23: 11.1074 | AF23: -0.3372 | AG23: 14.391278 | AH23: 5.4233191 | AI23: 11.107381 | AJ23: 10.715721 | AK23: 9.0968791
A24: 160 | B24: ALFA.ST | C24: Alfa Laval AB (publ) | D24: Industrials | E24: Sweden | F24: 212945715200 | G24: 0.2024 | H24: 0.0306 | I24: 0.98 | J24: 0.0382 | L24: 0.1044 | N24: 2503000000 | O24: 16.05 | P24: 2024 | Q24: 66954000000 | R24: 12738000000 | S24: 10320000000 | T24: 7391000000 | U24: 88803000000 | V24: 13592000000 | W24: 7369000000 | X24: 6223000000 | Y24: 3336000000 | Z24: 46085 | AA24: 515.8 | AB24: 413326315 | AC24: 13.2615 | AD24: 7.5781 | AE24: 11.02 | AF24: -0.3023 | AG24: 13.261478 | AH24: 7.5781028 | AI24: 11.020004 | AJ24: 10.884023 | AK24: 16.717359
A25: 15 | B25: JDW.L | C25: J D Wetherspoon plc | D25: Consumer Cyclical | E25: United Kingdom | F25: 715177344 | G25: 0.1131 | H25: 0.0871 | I25: 4.69 | J25: 0.0542 | K25: 3.42 | L25: 0.4721 | N25: 102382000 | O25: 8.89 | P25: 2024 | Q25: 2035500000 | R25: 230222000 | S25: 127840000 | T25: 48785000 | U25: 1904370000 | V25: 1137376000 | W25: 57233000 | X25: 1080143000 | Y25: 110266000 | Z25: 46083 | AA25: 706.5 | AB25: 105405650 | AC25: 16.0011 | AD25: 4.6758 | AE25: 5.4368 | AF25: -2.5563 | AG25: 16.001121 | AH25: 4.6758074 | AI25: 5.4368058 | AJ25: 9.4342325 | AK25: 3.1064683
A26: 16 | B26: SBT.PA | C26: Oeneo SA | D26: Consumer Defensive | E26: France | F26: 597083584 | G26: 0.2115 | H26: 0.0636 | I26: 0.88 | J26: 0.0494 | K26: 12.08 | L26: -0.0186 | N26: 20371000 | O26: 11.16 | P26: 2024 | Q26: 305728000 | R26: 63293000 | S26: 42048000 | T26: 28850000 | U26: 501741000 | V26: 104608000 | W26: 40370000 | X26: 64238000 | Y26: 21536000 | Z26: 46083 | AA26: 9.24 | AB26: 64340909 | AC26: 14.8616 | AD26: 7.8739 | AE26: 11.4755 | AF26: -0.1852 | AG26: 14.861624 | AH26: 7.8738574 | AI26: 11.475478 | AJ26: 11.74945 | AK26: 9.4336433
A27: 105 | B27: ANA.MC | C27: Acciona, S.A. | D27: Industrials | E27: Spain | F27: 12034308096 | G27: 0.1335 | H27: -0.0409 | I27: 3.25 | J27: 0.1423 | L27: 0.2341 | N27: 1372000000 | O27: 7.32 | P27: 2024 | Q27: 19190000000 | R27: 2562000000 | S27: 1423000000 | T27: 422000000 | U27: 34620000000 | V27: 12556000000 | W27: 4240000000 | X27: 8316000000 | Y27: 2731000000 | Z27: 46085 | AA27: 220.4 | AB27: 54503208 | AC27: 9.7945 | AD27: 5.3388 | AE27: 6.4464 | AF27: -1.8471 | AG27: 9.7944965 | AH27: 5.3388178 | AI27: 6.4464025 | AJ27: 7.4533647 | AK27: 4.6972319
A28: 17 | B28: GPE.L | C28: Great Portland Estates Plc | D28: Real Estate | E28: United Kingdom | F28: 1315115776 | G28: 1.4034 | H28: -0.0035 | I28: 6.93 | J28: 0.0064 | K28: 10.41 | L28: 0.0389 | N28: 1700000 | O28: 71.98 | P28: 2024 | Q28: 95400000 | R28: -288600000 | S28: -290200000 | T28: -307800000 | U28: 2478000000 | V28: 815500000 | W28: 5900000 | X28: 809600000 | Y28: 100000 | Z28: 46083 | AA28: 339 | AB28: 403409734 | AC28: 11.608 | AD28: 25 | AE28: 4.5951 | AF28: -2.4788 | AG28: 11.607995 | AH28: 25 | AI28: 4.5951216 | AJ28: 13.521734 | AK28: -4.5568807
A29: 44 | B29: IWG.L | C29: International Workplace Group plc | D29: Real Estate | E29: Switzerland | F29: 2029408768 | G29: 0.4976 | H29: 0.5381 | I29: 3.74 | J29: 0.0642 | K29: 4.18 | L29: 0.073 | N29: 1344000000 | O29: 19.61 | P29: 2024 | Q29: 3690000000 | R29: 1836000000 | S29: 492000000 | T29: 20000000 | U29: 9633000000 | V29: 6995000000 | W29: 137000000 | X29: 6858000000 | Y29: 237000000 | Z29: 46083 | AA29: 212.4 | AB29: 988797019 | AC29: 25 | AD29: 17.1723 | AE29: 6.034 | AF29: -0.8935 | AG29: 25 | AH29: 17.172253 | AI29: 6.0340055 | AJ29: 16.961877 | AK29: 1.1053425
A30: 18 | B30: VIRP.PA | C30: Virbac SA | D30: Healthcare | E30: France | F30: 2894538240 | G30: 0.1977 | H30: 0.0428 | I30: 0.57 | J30: 0.0576 | K30: 24.85 | L30: 0.0963 | N30: 57352000 | O30: 11.87 | P30: 2024 | Q30: 1397379000 | R30: 276264000 | S30: 218912000 | T30: 145290000 | U30: 1848522000 | V30: 307014000 | W30: 149631000 | X30: 157383000 | Y30: 80439000 | Z30: 46083 | AA30: 362 | AB30: 8377824 | AC30: 13.853 | AD30: 7.4254 | AE30: 13.2562 | AF30: -0.0448 | AG30: 13.853047 | AH30: 7.4253504 | AI30: 13.256178 | AJ30: 11.745677 | AK30: 10.477435
A31: 96 | B31: ARGX.BR | C31: argenx SE | D31: Healthcare | E31: Netherlands | F31: 40100450304 | G31: 0.048 | H31: -0.0038 | I31: -13.89 | J31: 0.0312 | L31: 0.8659 | N31: 17527000 | O31: 32.34 | P31: 2024 | Q31: 2190231000 | R31: 105171000 | S31: 87644000 | T31: 833040000 | U31: 6202522000 | V31: 39053000 | W31: 1499936000 | X31: -1460883000 | Y31: 68301000 | Z31: 46085 | AA31: 648.2 | AB31: 61883406 | AC31: 11.5934 | AD31: 2.56 | AE31: 1.1418 | AF31: 8.3863 | AG31: 11.593448 | AH31: 2.5600244 | AI31: 1.1417667 | AJ31: 5.7479165 | AK31: 381.2881
A32: 19 | B32: BSLN.SW | C32: Basilea Pharmaceutica AG | D32: Healthcare | E32: Switzerland | F32: 646716672 | G32: 0.2197 | H32: 0.0916 | I32: -1.38 | J32: 0.0123 | K32: 15.21 | L32: 0.168 | N32: 1814000 | O32: 10.88 | P32: 2024 | Q32: 208543000 | R32: 66336000 | S32: 64604000 | T32: 77593000 | U32: 257764000 | V32: 111671000 | W32: 120700000 | X32: -9029000 | Y32: 1792000 | Z32: 46083 | AA32: 54.2 | AB32: 12271663 | AC32: 16.2193 | AD32: 8.1404 | AE32: 1 | AF32: 1.2199 | AG32: 16.219323 | AH32: 8.1403616 | AI32: 1 | AJ32: 9.2298377 | AK32: 9.7491056
A33: 20 | B33: TRE.MC | C33: Técnicas Reunidas, S.A. | D33: Industrials | E33: Spain | F33: 2250756096 | G33: 0.0491 | H33: 0.0337 | I33: -0.59 | J33: 0.0016 | K33: 5.48 | L33: 0.1686 | N33: 9362000 | O33: 7.89 | P33: 2024 | Q33: 4451446000 | R33: 218784000 | S33: 185875000 | T33: 89942000 | U33: 4629235000 | V33: 888637000 | W33: 1018409000 | X33: -129772000 | Y33: 7256000 | Z33: 46083 | AA33: 35.3 | AB33: 78097009 | AC33: 13.4118 | AD33: 2.5958 | AE33: 25 | AF33: 0.4601 | AG33: 13.411795 | AH33: 2.5957749 | AI33: 25 | AJ33: 13.64345 | AK33: 10.287572
A34: 21 | B34: FAN.L | C34: Volution Group plc | D34: Industrials | E34: United Kingdom | F34: 1303555328 | G34: 0.2381 | H34: 0.0524 | I34: 0.82 | J34: 0.0212 | K34: 14 | L34: 0.0849 | N34: 20280000 | O34: 16.27 | P34: 2024 | Q34: 347611000 | R34: 82763000 | S34: 62483000 | T34: 42797000 | U34: 430315000 | V34: 85993000 | W34: 18243000 | X34: 67750000 | Y34: 7382000 | Z34: 46083 | AA34: 691 | AB34: 198410249 | AC34: 14.3185 | AD34: 8.7384 | AE34: 11.7728 | AF34: -0.1329 | AG34: 14.318544 | AH34: 8.7383709 | AI34: 11.772787 | AJ34: 11.880765 | AK34: 15.75046
A35: 22 | B35: BOSS.DE | C35: Hugo Boss AG | D35: Consumer Cyclical | E35: Germany | F35: 2419016704 | G35: 0.1792 | H35: 0.206 | I35: 1.34 | J35: 0.0667 | K35: 13.73 | L35: 0.1621 | N35: 414206000 | O35: 11.63 | P35: 2024 | Q35: 4307349000 | R35: 771940000 | S35: 357734000 | T35: 213468000 | U35: 3782421000 | V35: 1248211000 | W35: 210622000 | X35: 1037589000 | Y35: 287190000 | Z35: 46083 | AA35: 36.22 | AB35: 69016167 | AC35: 21.7665 | AD35: 6.8241 | AE35: 9.7026 | AF35: -0.3006 | AG35: 21.766494 | AH35: 6.824091 | AI35: 9.7026333 | AJ35: 13.664615 | AK35: 3.1336849
A36: 27 | B36: ATO.PA | C36: Atos SE | D36: Technology | E36: France | F36: 741217216 | G36: 0.147 | H36: -2.4905 | I36: 0.76 | J36: 0.0464 | K36: 3.72 | L36: -0.0386 | N36: 568000000 | O36: 15.61 | P36: 2024 | Q36: 9577000000 | R36: 1408000000 | S36: 840000000 | T36: 248000000 | U36: 8246000000 | V36: 2811000000 | W36: 1739000000 | X36: 1072000000 | Y36: 444000000 | Z36: 46083 | AA36: 39.2825 | AB36: 19378227 | AC36: 1 | AD36: 5.7776 | AE36: 12.0904 | AF36: -3.7663 | AG36: 1 | AH36: 5.7775746 | AI36: 12.090368 | AJ36: 5.7603828 | AK36: 0.52643268
A37: 23 | B37: SMHN.DE | C37: SUSS MicroTec SE | D37: Technology | E37: Germany | F37: 1029371776 | G37: 0.193 | H37: 0.0252 | I37: -1.43 | J37: 0.017 | K37: 218.51 | L37: 0.2078 | N37: 7821000 | O37: 10.13 | P37: 2024 | Q37: 446147000 | R37: 86094000 | S37: 78273000 | T37: 110343000 | U37: 500873000 | V37: 13295000 | W37: 136239000 | X37: -122944000 | Y37: 7564000 | Z37: 46083 | AA37: 53.25 | AB37: 19115538 | AC37: 12.9996 | AD37: 7.2726 | AE37: 1 | AF37: 1.1249 | AG37: 12.999636 | AH37: 7.272598 | AI37: 1 | AJ37: 7.6816339 | AK37: 11.956371
A38: 24 | B38: TRN.L | C38: Trainline plc | D38: Consumer Cyclical | E38: United Kingdom | F38: 715123648 | G38: 0.2989 | H38: 0.1341 | I38: 0.62 | J38: 0.0957 | K38: 16.3 | L38: 0.3541 | N38: 43167000 | O38: 7.23 | P38: 2024 | Q38: 396718000 | R38: 98147000 | S38: 56485000 | T38: 33986000 | U38: 681933000 | V38: 153113000 | W38: 91085000 | X38: 62028000 | Y38: 39883000 | Z38: 46083 | AA38: 189.9 | AB38: 375519674 | AC38: 18.2801 | AD38: 10.7144 | AE38: 12.9229 | AF38: 0.1744 | AG38: 18.280116 | AH38: 10.714402 | AI38: 12.922873 | AJ38: 14.403229 | AK38: 7.2862507
A39: 112 | B39: BAB.L | C39: Babcock International Group PLC | D39: Industrials | E39: United Kingdom | F39: 6874880512 | G39: 0.1032 | H39: 0.0263 | I39: 0.76 | J39: 0.0266 | L39: 0.0572 | N39: 117700000 | O39: 14.75 | Z39: 46085 | AA39: 1380 | AB39: 498172502 | AC39: 13.053 | AD39: 4.3541 | AE39: 12.0904 | AF39: -0.2953 | AG39: 13.052975 | AH39: 4.3540524 | AI39: 12.090368 | AJ39: 10.154516
A40: 25 | B40: PROX.BR | C40: Proximus PLC | D40: Communication Services | E40: Belgium | F40: 2392254720 | G40: 0.3066 | H40: 0.0535 | I40: 2.2 | J40: 0.2312 | K40: 10.68 | L40: 0.0226 | N40: 1601000000 | O40: 2.96 | P40: 2024 | Q40: 6376000000 | R40: 1955000000 | S40: 696000000 | T40: 447000000 | U40: 13327000000 | V40: 4801000000 | W40: 497000000 | X40: 4304000000 | Y40: 1474000000 | Z40: 46083 | AA40: 7.295 | AB40: 322461674 | AC40: 14.3719 | AD40: 10.9647 | AE40: 7.7554 | AF40: -0.8772 | AG40: 14.371882 | AH40: 10.964656 | AI40: 7.7553945 | AJ40: 11.364768 | AK40: 1.2236597
...

Sheet country_tax
A1: country_name | B1: tax_rate
A2: United States | B2: 0.21
A3: France | B3: 0.25
A4: Germany | B4: 0.299
A5: United Kingdom | B5: 0.25
A6: Canada | B6: 0.265
A7: Brazil | B7: 0.34
A8: Belgium | B8: 0.25
A9: Bermuda | B9: 0
A10: Denmark | B10: 0.22
A11: Guernsey | B11: 0
A12: Hungary | B12: 0.09
A13: Italy | B13: 0.24
... A19: Switzerland | B19: 0.148

Sheet sector_benchmarks
A1: sector | B1: target_ebitda_mult | C1: annual_growth | D1: max_leverage | E1: nwc_variation_revenue | F1: capex_to_revenue | G1: ebitda_margin_target | H1: sector_beta
A2: Technology | B2: 15.5 | C2: 0.12 | D2: 3 | E2: 0.02 | F2: 0.04 | G2: 0.25 | H2: 1.2
A3: Healthcare | B3: 13 | C3: 0.07 | D3: 4 | E3: 0.03 | F3: 0.05 | G3: 0.2 | H3: 0.85
A4: Communication Services | B4: 9 | C4: 0.04 | D4: 4.5 | E4: 0.01 | F4: 0.12 | G4: 0.3 | H4: 1.05
A5: Consumer Cyclical | B5: 10.5 | C5: 0.05 | D5: 3.5 | E5: 0.06 | F5: 0.03 | G5: 0.15 | H5: 1.15
A6: Consumer Defensive | B6: 11 | C6: 0.03 | D6: 4.5 | E6: 0.04 | F6: 0.025 | G6: 0.12 | H6: 0.65
A7: Financial Services | B7: 10 | C7: 0.04 | D7: 7 | E7: 0 | F7: 0.01 | G7: 0.4 | H7: 1.1
A8: Industrials | B8: 9.5 | C8: 0.035 | D8: 3.5 | E8: 0.08 | F8: 0.06 | G8: 0.18 | H8: 1
A9: Energy | B9: 6 | C9: 0.02 | D9: 2.5 | E9: 0.03 | F9: 0.15 | G9: 0.35 | H9: 1.1
A10: Basic Materials | B10: 7.5 | C10: 0.025 | D10: 3 | E10: 0.1 | F10: 0.08 | G10: 0.22 | H10: 1.25
A11: Real Estate | B11: 16 | C11: 0.03 | D11: 8 | E11: 0.01 | F11: 0.05 | G11: 0.6 | H11: 0.7
A12: Utilities | B12: 10 | C12: 0.02 | D12: 6 | E12: 0.02 | F12: 0.2 | G12: 0.38 | H12: 0.5
